2024-11-20 14:07:17,845 - [modules.modules](DEBUG) - test
2024-11-20 15:34:59,486 - [rdetoolkit.workflows](ERROR) - 'module' object is not callable
Traceback (most recent call last):
  File "/Users/sonokawa/Desktop/develop-rdetoolkit/.venv/lib/python3.10/site-packages/rdetoolkit/workflows.py", line 212, in run
    for idx, rdeoutput_resource in enumerate(tqdm(generate_folder_paths_iterator(raw_files_group, invoice_org_filepath, invoice_schema_filepath))):
TypeError: 'module' object is not callable
2024-11-20 15:57:35,409 - [rdetoolkit.workflows](ERROR) - 'module' object is not callable
Traceback (most recent call last):
  File "/Users/sonokawa/Desktop/develop-rdetoolkit/.venv/lib/python3.10/site-packages/rdetoolkit/workflows.py", line 213, in run
    for idx, rdeoutput_resource in enumerate(tqdm(rde_data_tiles)):
TypeError: 'module' object is not callable
2024-11-20 15:59:35,921 - [rdetoolkit.workflows](ERROR) - 'module' object is not callable
Traceback (most recent call last):
  File "/Users/sonokawa/Desktop/develop-rdetoolkit/.venv/lib/python3.10/site-packages/rdetoolkit/workflows.py", line 213, in run
    for idx, rdeoutput_resource in enumerate(tqdm(rde_data_tiles)):
TypeError: 'module' object is not callable
2024-11-20 16:01:14,864 - [rdetoolkit.workflows](ERROR) - 'module' object is not callable
Traceback (most recent call last):
  File "/Users/sonokawa/Desktop/develop-rdetoolkit/.venv/lib/python3.10/site-packages/rdetoolkit/workflows.py", line 213, in run
    for idx, rdeoutput_resource in enumerate(tqdm(rde_data_tiles)):
TypeError: 'module' object is not callable
2024-11-20 16:03:40,724 - [rdetoolkit.workflows](ERROR) - 'module' object is not callable
Traceback (most recent call last):
  File "/Users/sonokawa/Desktop/develop-rdetoolkit/.venv/lib/python3.10/site-packages/rdetoolkit/workflows.py", line 213, in run
    for idx, rdeoutput_resource in enumerate(tqdm(rde_data_tiles)):
TypeError: 'module' object is not callable
2024-11-20 16:06:14,502 - [rdetoolkit.workflows](ERROR) - 'module' object is not callable
Traceback (most recent call last):
  File "/Users/sonokawa/Desktop/develop-rdetoolkit/.venv/lib/python3.10/site-packages/rdetoolkit/workflows.py", line 213, in run
    for idx, rdeoutput_resource in enumerate(tqdm(rde_data_tiles)):
TypeError: 'module' object is not callable
2024-11-20 16:06:56,523 - [modules.modules](DEBUG) - test
2024-11-20 16:06:56,612 - [modules.modules](DEBUG) - test
2024-11-20 16:06:56,693 - [modules.modules](DEBUG) - test
2025-02-04 16:15:53,654 - [rdetoolkit.workflows](ERROR) - Error: Test Error Message!!
Traceback (most recent call last):
  File "/Users/sonokawa/.pyenv/versions/3.10.10/lib/python3.10/site-packages/rdetoolkit/errors.py", line 43, in wrapper
    return func(*args, **kwargs)
  File "/Users/sonokawa/Desktop/work/develop-rdetoolkit/modules/modules.py", line 17, in success_modules
    logger.debug("test")
  File "/Users/sonokawa/Desktop/work/develop-rdetoolkit/modules/modules.py", line 17, in success_modules
    logger.debug("test")
  File "/Users/sonokawa/.pyenv/versions/3.10.10/lib/python3.10/bdb.py", line 90, in trace_dispatch
    return self.dispatch_line(frame)
  File "/Users/sonokawa/.pyenv/versions/3.10.10/lib/python3.10/bdb.py", line 115, in dispatch_line
    if self.quitting: raise BdbQuit
bdb.BdbQuit

The above exception was the direct cause of the following exception:

Traceback (most recent call last):
  File "/Users/sonokawa/.pyenv/versions/3.10.10/lib/python3.10/site-packages/rdetoolkit/workflows.py", line 221, in run
    status = multifile_mode_process(str(idx), srcpaths, rdeoutput_resource, custom_dataset_function)
  File "/Users/sonokawa/.pyenv/versions/3.10.10/lib/python3.10/site-packages/rdetoolkit/modeproc.py", line 161, in multifile_mode_process
    datasets_process_function(srcpaths, resource_paths)
  File "/Users/sonokawa/.pyenv/versions/3.10.10/lib/python3.10/site-packages/rdetoolkit/errors.py", line 48, in wrapper
    raise handle_exception(e, error_message=_emsg, error_code=_ecode, eobj=_eobj, verbose=verbose) from e
rdetoolkit.exceptions.StructuredError: Error: Test Error Message!!
2025-02-04 16:16:45,974 - [rdetoolkit.workflows](ERROR) - Error: Test Error Message!!
Traceback (most recent call last):
  File "/Users/sonokawa/.pyenv/versions/3.10.10/lib/python3.10/site-packages/rdetoolkit/errors.py", line 43, in wrapper
    return func(*args, **kwargs)
  File "/Users/sonokawa/Desktop/work/develop-rdetoolkit/modules/modules.py", line 17, in success_modules
    logger.debug("test")
  File "/Users/sonokawa/Desktop/work/develop-rdetoolkit/modules/modules.py", line 17, in success_modules
    logger.debug("test")
  File "/Users/sonokawa/.pyenv/versions/3.10.10/lib/python3.10/bdb.py", line 90, in trace_dispatch
    return self.dispatch_line(frame)
  File "/Users/sonokawa/.pyenv/versions/3.10.10/lib/python3.10/bdb.py", line 115, in dispatch_line
    if self.quitting: raise BdbQuit
bdb.BdbQuit

The above exception was the direct cause of the following exception:

Traceback (most recent call last):
  File "/Users/sonokawa/.pyenv/versions/3.10.10/lib/python3.10/site-packages/rdetoolkit/workflows.py", line 221, in run
    status = multifile_mode_process(str(idx), srcpaths, rdeoutput_resource, custom_dataset_function)
  File "/Users/sonokawa/.pyenv/versions/3.10.10/lib/python3.10/site-packages/rdetoolkit/modeproc.py", line 161, in multifile_mode_process
    datasets_process_function(srcpaths, resource_paths)
  File "/Users/sonokawa/.pyenv/versions/3.10.10/lib/python3.10/site-packages/rdetoolkit/errors.py", line 48, in wrapper
    raise handle_exception(e, error_message=_emsg, error_code=_ecode, eobj=_eobj, verbose=verbose) from e
rdetoolkit.exceptions.StructuredError: Error: Test Error Message!!
2025-02-04 16:53:07,963 - [rdetoolkit.workflows](ERROR) - Error: Test Error Message!!
Traceback (most recent call last):
  File "/Users/sonokawa/.pyenv/versions/3.10.10/lib/python3.10/site-packages/rdetoolkit/errors.py", line 43, in wrapper
    return func(*args, **kwargs)
  File "/Users/sonokawa/Desktop/work/develop-rdetoolkit/modules/modules.py", line 17, in success_modules
    logger.debug("test")
  File "/Users/sonokawa/Desktop/work/develop-rdetoolkit/modules/modules.py", line 17, in success_modules
    logger.debug("test")
  File "/Users/sonokawa/.pyenv/versions/3.10.10/lib/python3.10/bdb.py", line 90, in trace_dispatch
    return self.dispatch_line(frame)
  File "/Users/sonokawa/.pyenv/versions/3.10.10/lib/python3.10/bdb.py", line 115, in dispatch_line
    if self.quitting: raise BdbQuit
bdb.BdbQuit

The above exception was the direct cause of the following exception:

Traceback (most recent call last):
  File "/Users/sonokawa/.pyenv/versions/3.10.10/lib/python3.10/site-packages/rdetoolkit/workflows.py", line 221, in run
    status = multifile_mode_process(str(idx), srcpaths, rdeoutput_resource, custom_dataset_function)
  File "/Users/sonokawa/.pyenv/versions/3.10.10/lib/python3.10/site-packages/rdetoolkit/modeproc.py", line 161, in multifile_mode_process
    datasets_process_function(srcpaths, resource_paths)
  File "/Users/sonokawa/.pyenv/versions/3.10.10/lib/python3.10/site-packages/rdetoolkit/errors.py", line 48, in wrapper
    raise handle_exception(e, error_message=_emsg, error_code=_ecode, eobj=_eobj, verbose=verbose) from e
rdetoolkit.exceptions.StructuredError: Error: Test Error Message!!
2025-03-31 14:35:05,078 - [rdetoolkit.workflows](ERROR) - Error: Test Error Message!!
Traceback (most recent call last):
  File "/Users/sonokawa/Desktop/work/develop-rdetoolkit/.venv/lib/python3.10/site-packages/rdetoolkit/errors.py", line 43, in wrapper
    return func(*args, **kwargs)
  File "/Users/sonokawa/Desktop/work/develop-rdetoolkit/container/modules/modules.py", line 17, in success_modules
    logger.debug("test")
  File "/Users/sonokawa/Desktop/work/develop-rdetoolkit/container/modules/modules.py", line 17, in success_modules
    logger.debug("test")
  File "/Users/sonokawa/.pyenv/versions/3.10.10/lib/python3.10/bdb.py", line 90, in trace_dispatch
    return self.dispatch_line(frame)
  File "/Users/sonokawa/.pyenv/versions/3.10.10/lib/python3.10/bdb.py", line 115, in dispatch_line
    if self.quitting: raise BdbQuit
bdb.BdbQuit

The above exception was the direct cause of the following exception:

Traceback (most recent call last):
  File "/Users/sonokawa/Desktop/work/develop-rdetoolkit/.venv/lib/python3.10/site-packages/rdetoolkit/workflows.py", line 221, in run
    status = multifile_mode_process(str(idx), srcpaths, rdeoutput_resource, custom_dataset_function)
  File "/Users/sonokawa/Desktop/work/develop-rdetoolkit/.venv/lib/python3.10/site-packages/rdetoolkit/modeproc.py", line 161, in multifile_mode_process
    datasets_process_function(srcpaths, resource_paths)
  File "/Users/sonokawa/Desktop/work/develop-rdetoolkit/.venv/lib/python3.10/site-packages/rdetoolkit/errors.py", line 48, in wrapper
    raise handle_exception(e, error_message=_emsg, error_code=_ecode, eobj=_eobj, verbose=verbose) from e
rdetoolkit.exceptions.StructuredError: Error: Test Error Message!!
2025-03-31 14:35:23,447 - [modules.modules](DEBUG) - test
2025-03-31 14:35:23,527 - [modules.modules](DEBUG) - test
2025-03-31 14:35:23,623 - [modules.modules](DEBUG) - test
2025-03-31 14:45:32,771 - [modules.modules](DEBUG) - test
2025-03-31 14:45:32,774 - [rdetoolkit.workflows](ERROR) - Error: Test Error Message!!
Traceback (most recent call last):
  File "/Users/sonokawa/Desktop/work/develop-rdetoolkit/.venv/lib/python3.10/site-packages/rdetoolkit/errors.py", line 43, in wrapper
    return func(*args, **kwargs)
  File "/Users/sonokawa/Desktop/work/develop-rdetoolkit/container/modules/modules.py", line 73, in success_modules
    m = MetaParser(data)
TypeError: MetaParser() takes no arguments

The above exception was the direct cause of the following exception:

Traceback (most recent call last):
  File "/Users/sonokawa/Desktop/work/develop-rdetoolkit/.venv/lib/python3.10/site-packages/rdetoolkit/workflows.py", line 221, in run
    status = multifile_mode_process(str(idx), srcpaths, rdeoutput_resource, custom_dataset_function)
  File "/Users/sonokawa/Desktop/work/develop-rdetoolkit/.venv/lib/python3.10/site-packages/rdetoolkit/modeproc.py", line 161, in multifile_mode_process
    datasets_process_function(srcpaths, resource_paths)
  File "/Users/sonokawa/Desktop/work/develop-rdetoolkit/.venv/lib/python3.10/site-packages/rdetoolkit/errors.py", line 48, in wrapper
    raise handle_exception(e, error_message=_emsg, error_code=_ecode, eobj=_eobj, verbose=verbose) from e
rdetoolkit.exceptions.StructuredError: Error: Test Error Message!!
2025-03-31 14:47:02,433 - [modules.modules](DEBUG) - test
2025-03-31 14:47:02,439 - [rdetoolkit.workflows](ERROR) - Error: Test Error Message!!
Traceback (most recent call last):
  File "/Users/sonokawa/Desktop/work/develop-rdetoolkit/.venv/lib/python3.10/site-packages/rdetoolkit/errors.py", line 43, in wrapper
    return func(*args, **kwargs)
  File "/Users/sonokawa/Desktop/work/develop-rdetoolkit/container/modules/modules.py", line 78, in success_modules
    meta = Meta(a.tasksupport.joinpath("metadata-def.json"))
  File "/Users/sonokawa/Desktop/work/develop-rdetoolkit/.venv/lib/python3.10/site-packages/rdetoolkit/rde2util.py", line 330, in __init__
    self.metaDef: dict[str, MetadataDefJson] = self._read_metadef_file(metadef_filepath)
  File "/Users/sonokawa/Desktop/work/develop-rdetoolkit/.venv/lib/python3.10/site-packages/rdetoolkit/rde2util.py", line 352, in _read_metadef_file
    if vdef.get("action"):
AttributeError: 'list' object has no attribute 'get'

The above exception was the direct cause of the following exception:

Traceback (most recent call last):
  File "/Users/sonokawa/Desktop/work/develop-rdetoolkit/.venv/lib/python3.10/site-packages/rdetoolkit/workflows.py", line 221, in run
    status = multifile_mode_process(str(idx), srcpaths, rdeoutput_resource, custom_dataset_function)
  File "/Users/sonokawa/Desktop/work/develop-rdetoolkit/.venv/lib/python3.10/site-packages/rdetoolkit/modeproc.py", line 161, in multifile_mode_process
    datasets_process_function(srcpaths, resource_paths)
  File "/Users/sonokawa/Desktop/work/develop-rdetoolkit/.venv/lib/python3.10/site-packages/rdetoolkit/errors.py", line 48, in wrapper
    raise handle_exception(e, error_message=_emsg, error_code=_ecode, eobj=_eobj, verbose=verbose) from e
rdetoolkit.exceptions.StructuredError: Error: Test Error Message!!
2025-03-31 14:47:32,120 - [modules.modules](DEBUG) - test
2025-03-31 14:47:32,130 - [rdetoolkit.workflows](ERROR) - Error: Test Error Message!!
Traceback (most recent call last):
  File "/Users/sonokawa/Desktop/work/develop-rdetoolkit/.venv/lib/python3.10/site-packages/rdetoolkit/errors.py", line 43, in wrapper
    return func(*args, **kwargs)
  File "/Users/sonokawa/Desktop/work/develop-rdetoolkit/container/modules/modules.py", line 78, in success_modules
    meta = Meta(a.tasksupport.joinpath("metadata-def.json"))
  File "/Users/sonokawa/Desktop/work/develop-rdetoolkit/.venv/lib/python3.10/site-packages/rdetoolkit/rde2util.py", line 330, in __init__
    self.metaDef: dict[str, MetadataDefJson] = self._read_metadef_file(metadef_filepath)
  File "/Users/sonokawa/Desktop/work/develop-rdetoolkit/.venv/lib/python3.10/site-packages/rdetoolkit/rde2util.py", line 352, in _read_metadef_file
    if vdef.get("action"):
AttributeError: 'list' object has no attribute 'get'

The above exception was the direct cause of the following exception:

Traceback (most recent call last):
  File "/Users/sonokawa/Desktop/work/develop-rdetoolkit/.venv/lib/python3.10/site-packages/rdetoolkit/workflows.py", line 221, in run
    status = multifile_mode_process(str(idx), srcpaths, rdeoutput_resource, custom_dataset_function)
  File "/Users/sonokawa/Desktop/work/develop-rdetoolkit/.venv/lib/python3.10/site-packages/rdetoolkit/modeproc.py", line 161, in multifile_mode_process
    datasets_process_function(srcpaths, resource_paths)
  File "/Users/sonokawa/Desktop/work/develop-rdetoolkit/.venv/lib/python3.10/site-packages/rdetoolkit/errors.py", line 48, in wrapper
    raise handle_exception(e, error_message=_emsg, error_code=_ecode, eobj=_eobj, verbose=verbose) from e
rdetoolkit.exceptions.StructuredError: Error: Test Error Message!!
2025-03-31 14:49:08,847 - [modules.modules](DEBUG) - test
2025-03-31 14:49:34,260 - [rdetoolkit.workflows](ERROR) - Error: Test Error Message!!
Traceback (most recent call last):
  File "/Users/sonokawa/Desktop/work/develop-rdetoolkit/.venv/lib/python3.10/site-packages/rdetoolkit/errors.py", line 43, in wrapper
    return func(*args, **kwargs)
  File "/Users/sonokawa/Desktop/work/develop-rdetoolkit/container/modules/modules.py", line 78, in success_modules
    meta = Meta(a.tasksupport.joinpath("metadata-def.json"))
  File "/Users/sonokawa/Desktop/work/develop-rdetoolkit/.venv/lib/python3.10/site-packages/rdetoolkit/rde2util.py", line 330, in __init__
    self.metaDef: dict[str, MetadataDefJson] = self._read_metadef_file(metadef_filepath)
  File "/Users/sonokawa/Desktop/work/develop-rdetoolkit/.venv/lib/python3.10/site-packages/rdetoolkit/rde2util.py", line 352, in _read_metadef_file
    if vdef.get("action"):
AttributeError: 'list' object has no attribute 'get'

The above exception was the direct cause of the following exception:

Traceback (most recent call last):
  File "/Users/sonokawa/Desktop/work/develop-rdetoolkit/.venv/lib/python3.10/site-packages/rdetoolkit/workflows.py", line 221, in run
    status = multifile_mode_process(str(idx), srcpaths, rdeoutput_resource, custom_dataset_function)
  File "/Users/sonokawa/Desktop/work/develop-rdetoolkit/.venv/lib/python3.10/site-packages/rdetoolkit/modeproc.py", line 161, in multifile_mode_process
    datasets_process_function(srcpaths, resource_paths)
  File "/Users/sonokawa/Desktop/work/develop-rdetoolkit/.venv/lib/python3.10/site-packages/rdetoolkit/errors.py", line 48, in wrapper
    raise handle_exception(e, error_message=_emsg, error_code=_ecode, eobj=_eobj, verbose=verbose) from e
rdetoolkit.exceptions.StructuredError: Error: Test Error Message!!
2025-03-31 14:49:41,271 - [modules.modules](DEBUG) - test
2025-03-31 14:50:39,365 - [modules.modules](DEBUG) - test
2025-03-31 14:50:43,423 - [rdetoolkit.workflows](ERROR) - Error: Test Error Message!!
Traceback (most recent call last):
  File "/Users/sonokawa/Desktop/work/develop-rdetoolkit/.venv/lib/python3.10/site-packages/rdetoolkit/errors.py", line 43, in wrapper
    return func(*args, **kwargs)
  File "/Users/sonokawa/Desktop/work/develop-rdetoolkit/container/modules/modules.py", line 78, in success_modules
    meta = Meta(a.tasksupport.joinpath("metadata-def.json"))
  File "/Users/sonokawa/Desktop/work/develop-rdetoolkit/.venv/lib/python3.10/site-packages/rdetoolkit/rde2util.py", line 330, in __init__
    self.metaDef: dict[str, MetadataDefJson] = self._read_metadef_file(metadef_filepath)
  File "/Users/sonokawa/Desktop/work/develop-rdetoolkit/.venv/lib/python3.10/site-packages/rdetoolkit/rde2util.py", line 352, in _read_metadef_file
    if vdef.get("action"):
AttributeError: 'list' object has no attribute 'get'

The above exception was the direct cause of the following exception:

Traceback (most recent call last):
  File "/Users/sonokawa/Desktop/work/develop-rdetoolkit/.venv/lib/python3.10/site-packages/rdetoolkit/workflows.py", line 221, in run
    status = multifile_mode_process(str(idx), srcpaths, rdeoutput_resource, custom_dataset_function)
  File "/Users/sonokawa/Desktop/work/develop-rdetoolkit/.venv/lib/python3.10/site-packages/rdetoolkit/modeproc.py", line 161, in multifile_mode_process
    datasets_process_function(srcpaths, resource_paths)
  File "/Users/sonokawa/Desktop/work/develop-rdetoolkit/.venv/lib/python3.10/site-packages/rdetoolkit/errors.py", line 48, in wrapper
    raise handle_exception(e, error_message=_emsg, error_code=_ecode, eobj=_eobj, verbose=verbose) from e
rdetoolkit.exceptions.StructuredError: Error: Test Error Message!!
2025-03-31 14:52:03,793 - [modules.modules](DEBUG) - test
